Workbook

Sheet README
A1: Verified Stock Inventory Master — Guide
A3: What this is | B3: A cleaned, categorised product master built from StockSummaryReport_10_10_26.xlsx (sheet "Stock Summary Report", dated 10-10-26). Every source row is traceable via the Source Reference column.
A4: Sheets
A5: • Product Master | B5: One row per source product record (2,502 rows). SKU stored as text. Use the Excel Table filters to sort/search. Category, Subcategory and Verification Status have dropdown validation (lists on the hidden Lists sheet). Column T (SKU Unique Weight) is a helper for the Category Summary unique-SKU counts.
A6: • Category Summary | B6: Counts and stock totals per Category/Subcategory, calculated with COUNTIFS/SUMIFS formulas from Product Master. The TOTAL row sums the table.
A7: • SKU & Data Quality Audit | B7: Every record needing attention: missing SKUs, duplicate/conflicting SKUs, negative quantities, unclassified products, zero purchase prices, and fallback-rule classifications. Work through this sheet to resolve issues.
A8: • Source Reconciliation | B8: All 2,507 source rows with their original values, final mapping, and outcome (Mapped / Excluded). Use it to prove nothing was dropped.
A9: • Vehicle Compatibility | B9: One row per product with bike fitment found in the source name. Fitment was extracted from text only — verify against manufacturer charts before committing to a customer.
A10: Key rules applied
A11: • SKUs | B11: Extracted exactly as written in the source (prefix codes like WIN2053, parenthetical codes like (SBH170026)). Never invented. "Missing SKU" where none was found.
A12: • Verification Status | B12: "Source-Parsed" = confidently parsed from source text (not externally verified). "Needs Verification" = ambiguous product, fallback classification, or unclassified.
A13: • Excluded rows | B13: 5 non-product lines (CGST @14%, SGST@14%, TAXX, SHIPPING, TRANSPORTATION CHARGES) were excluded from the catalogue and are documented in Source Reconciliation.
A14: • Duplicates | B14: 28 SKUs appear on multiple rows (mostly spelling variants of the same item name). Rows were kept separate so stock quantities reconcile exactly; see the Audit sheet to decide merges.
A15: • External Verification | B15: Every product was checked against external sources (manufacturer sites, official distributors, major moto retailers) in Oct 2026, including a second pass that infers the brand from famous product lines (e.g. 7100 4T → Motul) and fixes obvious typos in names (91 typos corrected). "Externally Verified" = exact SKU or brand+model found on a credible source (evidence link in Verification Evidence). "Probable Match" = identified as most probably this item — right brand/product family, minor variant differences; see the evidence link. "Not Found Externally" = no convincing match — treat the name with caution. "N/A — Generic/Unbranded" = generic item with no brand/SKU; no manufacturer source can confirm it. Note: internal shop codes (e.g. SBH*, WIN*, TTD*) mostly have no external footprint and land in Not Found Externally.
A16: Reconciliation counts
A17: Total source product rows | B17: 2507
A18: Rows mapped to Product Master | B18: 2502
A19: Rows excluded (non-product) | B19: 5
A20: Distinct products in catalogue | B20: 2502
A21: Unique SKUs | B21: 492
A22: Missing SKUs | B22: 1980
A23: Duplicate/conflicting SKU groups | B23: 28
A24: Classified products | B24: 2423
A25: Unclassified products | B25: 79
A26: Needs Verification | B26: 325
A27: Source stock quantity total | B27: 5924
A28: Externally Verified | B28: 1579
... A31: N/A — Generic/Unbranded | B31: 303

Sheet Product Master
A1: SKU | B1: Product Name | C1: Category | D1: Subcategory | E1: Brand | F1: Model / Series | G1: Colour | H1: Size / Variant | I1: Compatible Bike Make | J1: Compatible Bike Model | K1: Product Description | L1: Stock Quantity | M1: Sale Price | N1: Purchase Price | O1: Available Quantity | P1: Reserved Quantity | Q1: Stock Value | R1: Verification Status | S1: Source Reference | T1: SKU Unique Weight | U1: External Verification | V1: Verification Evidence
A2: Missing SKU | B2: BOOT RAIN COVER | C2: Covers | D2: Bike Covers | K2: BOOT RAIN COVER (SKU: Missing SKU). | L2: 4 | M2: 0 | N2: 42.37 | O2: 4 | P2: 0 | Q2: 169.48 | R2: Source-Parsed | S2: Stock Summary Report — Row 5 | T2: =IF(A2="Missing SKU",0,1/COUNTIFS($A$2:$A$2503,A2)) | U2: N/A — Generic/Unbranded
A3: Missing SKU | B3: CARRIER | C3: Luggage & Storage | D3: Carriers & Racks | K3: CARRIER (SKU: Missing SKU). | L3: -1 | M3: 1125 | N3: 62.5 | O3: -1 | P3: 0 | Q3: 0 | R3: Source-Parsed | S3: Stock Summary Report — Row 6 | T3: =IF(A3="Missing SKU",0,1/COUNTIFS($A$2:$A$2503,A3)) | U3: N/A — Generic/Unbranded
A4: Missing SKU | B4: CARRIER&BACKREST | C4: Body Parts & Panels | D4: Backrests | K4: CARRIER&BACKREST (SKU: Missing SKU). | L4: 0 | M4: 3200 | N4: 70.31 | O4: 0 | P4: 0 | Q4: 0 | R4: Source-Parsed | S4: Stock Summary Report — Row 7 | T4: =IF(A4="Missing SKU",0,1/COUNTIFS($A$2:$A$2503,A4)) | U4: N/A — Generic/Unbranded
A5: Missing SKU | B5: CG WITH SLIDER | C5: Crash Protection | D5: Crash Guards & Sliders | K5: CG WITH SLIDER (SKU: Missing SKU). | L5: 1 | M5: 0 | N5: 351.56 | O5: 1 | P5: 0 | Q5: 351.56 | R5: Source-Parsed | S5: Stock Summary Report — Row 8 | T5: =IF(A5="Missing SKU",0,1/COUNTIFS($A$2:$A$2503,A5)) | U5: N/A — Generic/Unbranded
A6: Missing SKU | B6: CHAIN CLEANER BRUSH RED AND BLACK | C6: Maintenance & Cleaning | D6: Chain Cleaners | G6: RED | K6: CHAIN CLEANER BRUSH RED AND BLACK (SKU: Missing SKU). Colour: RED. | L6: -2 | M6: 100 | N6: 6.25 | O6: -2 | P6: 0 | Q6: 0 | R6: Source-Parsed | S6: Stock Summary Report — Row 9 | T6: =IF(A6="Missing SKU",0,1/COUNTIFS($A$2:$A$2503,A6)) | U6: N/A — Generic/Unbranded
A7: Missing SKU | B7: CLOTH | C7: Maintenance & Cleaning | D7: Cleaning Products | K7: CLOTH (SKU: Missing SKU). | L7: 0 | M7: 100 | N7: 100 | O7: 0 | P7: 0 | Q7: 0 | R7: Source-Parsed | S7: Stock Summary Report — Row 10 | T7: =IF(A7="Missing SKU",0,1/COUNTIFS($A$2:$A$2503,A7)) | U7: N/A — Generic/Unbranded
A8: Missing SKU | B8: CRASHGUARD | C8: Crash Protection | D8: Crash Guards & Sliders | K8: CRASHGUARD (SKU: Missing SKU). | L8: 1 | M8: 6000 | N8: 390.62 | O8: 1 | P8: 0 | Q8: 359.38 | R8: Source-Parsed | S8: Stock Summary Report — Row 11 | T8: =IF(A8="Missing SKU",0,1/COUNTIFS($A$2:$A$2503,A8)) | U8: N/A — Generic/Unbranded
A9: Missing SKU | B9: HANDLE | C9: Mirrors & Handlebar Accessories | D9: Handlebar Controls | K9: HANDLE (SKU: Missing SKU). | L9: -1 | M9: 2500 | N9: 234.37 | O9: -1 | P9: 0 | Q9: 0 | R9: Source-Parsed | S9: Stock Summary Report — Row 12 | T9: =IF(A9="Missing SKU",0,1/COUNTIFS($A$2:$A$2503,A9)) | U9: N/A — Generic/Unbranded
A10: Missing SKU | B10: HAZARD | C10: Lighting & Electrical | D10: Indicators & Flashers | K10: HAZARD (SKU: Missing SKU). | L10: 7 | M10: 0 | N10: 84.74 | O10: 7 | P10: 0 | Q10: 593.18 | R10: Source-Parsed | S10: Stock Summary Report — Row 13 | T10: =IF(A10="Missing SKU",0,1/COUNTIFS($A$2:$A$2503,A10)) | U10: N/A — Generic/Unbranded
A11: Missing SKU | B11: HEAD MOUNT | C11: Unclassified — Needs Verification | K11: HEAD MOUNT (SKU: Missing SKU). | L11: 1 | M11: 350 | N11: 218.75 | O11: 1 | P11: 0 | Q11: 218.75 | R11: Needs Verification | S11: Stock Summary Report — Row 14 | T11: =IF(A11="Missing SKU",0,1/COUNTIFS($A$2:$A$2503,A11)) | U11: N/A — Generic/Unbranded
A12: Missing SKU | B12: HEADLIGHT SHIELD | C12: Lighting & Electrical | D12: Headlights | K12: HEADLIGHT SHIELD (SKU: Missing SKU). | L12: 0 | M12: 1099 | N12: 54.69 | O12: 0 | P12: 0 | Q12: 0 | R12: Source-Parsed | S12: Stock Summary Report — Row 15 | T12: =IF(A12="Missing SKU",0,1/COUNTIFS($A$2:$A$2503,A12)) | U12: N/A — Generic/Unbranded
A13: Missing SKU | B13: MICRO FIBER AND HELMET CAP | C13: Helmets | K13: MICRO FIBER AND HELMET CAP (SKU: Missing SKU). | L13: 13 | M13: 2300 | N13: 9.52 | O13: 13 | P13: 0 | Q13: 123.76 | R13: Source-Parsed | S13: Stock Summary Report — Row 16 | T13: =IF(A13="Missing SKU",0,1/COUNTIFS($A$2:$A$2503,A13)) | U13: N/A — Generic/Unbranded
A14: Missing SKU | B14: MOTORCYCLE TUBE CLAMP | C14: Tyres & Wheels | D14: Tyres | K14: MOTORCYCLE TUBE CLAMP (SKU: Missing SKU). | L14: 2 | M14: 450 | N14: 59.32 | O14: 2 | P14: 0 | Q14: 118.64 | R14: Source-Parsed | S14: Stock Summary Report — Row 17 | T14: =IF(A14="Missing SKU",0,1/COUNTIFS($A$2:$A$2503,A14)) | U14: N/A — Generic/Unbranded
A15: Missing SKU | B15: SADDLE STAY | C15: Luggage & Storage | D15: Saddle Stays | K15: SADDLE STAY (SKU: Missing SKU). | L15: 1 | M15: 0 | N15: 93.75 | O15: 1 | P15: 0 | Q15: 93.75 | R15: Source-Parsed | S15: Stock Summary Report — Row 18 | T15: =IF(A15="Missing SKU",0,1/COUNTIFS($A$2:$A$2503,A15)) | U15: N/A — Generic/Unbranded
A16: Missing SKU | B16: SADDLESTAY | C16: Luggage & Storage | D16: Saddle Stays | K16: SADDLESTAY (SKU: Missing SKU). | L16: 1 | M16: 0 | N16: 507.81 | O16: 1 | P16: 0 | Q16: 507.81 | R16: Source-Parsed | S16: Stock Summary Report — Row 19 | T16: =IF(A16="Missing SKU",0,1/COUNTIFS($A$2:$A$2503,A16)) | U16: N/A — Generic/Unbranded
A17: Missing SKU | B17: SCALE MODEL HELMET | C17: Merchandise & Decals | D17: Scale Models | K17: SCALE MODEL HELMET (SKU: Missing SKU). | L17: 6 | M17: 1400 | N17: 101.7 | O17: 6 | P17: 0 | Q17: 560.6 | R17: Source-Parsed | S17: Stock Summary Report — Row 20 | T17: =IF(A17="Missing SKU",0,1/COUNTIFS($A$2:$A$2503,A17)) | U17: N/A — Generic/Unbranded
A18: Missing SKU | B18: SUCTION MAGNETIC SMALL ROD | C18: Unclassified — Needs Verification | K18: SUCTION MAGNETIC SMALL ROD (SKU: Missing SKU). | L18: 1 | M18: 0 | N18: 39.06 | O18: 1 | P18: 0 | Q18: 39.06 | R18: Needs Verification | S18: Stock Summary Report — Row 21 | T18: =IF(A18="Missing SKU",0,1/COUNTIFS($A$2:$A$2503,A18)) | U18: N/A — Generic/Unbranded
A19: Missing SKU | B19: TOPCASE | C19: Luggage & Storage | D19: Top Boxes | K19: TOPCASE (SKU: Missing SKU). | L19: -1 | M19: 5800 | N19: 335.94 | O19: -1 | P19: 0 | Q19: 0 | R19: Source-Parsed | S19: Stock Summary Report — Row 22 | T19: =IF(A19="Missing SKU",0,1/COUNTIFS($A$2:$A$2503,A19)) | U19: N/A — Generic/Unbranded
A20: Missing SKU | B20: WINGLET | C20: Body Parts & Panels | D20: Winglets | K20: WINGLET (SKU: Missing SKU). | L20: 0 | M20: 78.13 | N20: 19.53 | O20: 0 | P20: 0 | Q20: 0 | R20: Source-Parsed | S20: Stock Summary Report — Row 23 | T20: =IF(A20="Missing SKU",0,1/COUNTIFS($A$2:$A$2503,A20)) | U20: N/A — Generic/Unbranded
A21: Missing SKU | B21: 100% GLASSES | C21: Helmets | D21: Riding Eyewear | E21: 100% | F21: GLASSES | K21: 100% GLASSES (SKU: Missing SKU). Brand: 100%. Model/Series: GLASSES. | L21: 4 | M21: 1250 | N21: 600 | O21: 4 | P21: 0 | Q21: 2033.9 | R21: Source-Parsed | S21: Stock Summary Report — Row 24 | T21: =IF(A21="Missing SKU",0,1/COUNTIFS($A$2:$A$2503,A21)) | U21: Probable Match | V21: https://www.motosport.com/100-percent?mmy=KAWASAKI%3BKLX140L%3B2024&shopallrlp=1-dirt-bike-parts
A22: Missing SKU | B22: 12LED STRIP 2*14 | C22: Lighting & Electrical | D22: LED Accessories | K22: 12LED STRIP 2*14 (SKU: Missing SKU). | L22: 5 | M22: 0 | N22: 105 | O22: 5 | P22: 0 | Q22: 444.92 | R22: Source-Parsed | S22: Stock Summary Report — Row 25 | T22: =IF(A22="Missing SKU",0,1/COUNTIFS($A$2:$A$2503,A22)) | U22: N/A — Generic/Unbranded
A23: 177 | B23: BAR END Mirror CHROME PLATED | C23: Mirrors & Handlebar Accessories | D23: Mirrors | G23: CHROME | K23: BAR END Mirror CHROME PLATED (SKU: 177). Colour: CHROME. | L23: 12 | M23: 1100 | N23: 500 | O23: 12 | P23: 0 | Q23: 6048.73 | R23: Source-Parsed | S23: Stock Summary Report — Row 26 | T23: =IF(A23="Missing SKU",0,1/COUNTIFS($A$2:$A$2503,A23)) | U23: Probable Match | V23: https://www.alchemyparts.co.uk/pair-of-chrome-round-bar-end-motorcycle-motorbike-mirrors/
A24: Missing SKU | B24: 2 LED FEATURE FOG LAMP USERIES | C24: Lighting & Electrical | D24: Auxiliary Lights | K24: 2 LED FEATURE FOG LAMP USERIES (SKU: Missing SKU). | L24: 1 | M24: 0 | N24: 400 | O24: 1 | P24: 0 | Q24: 400 | R24: Source-Parsed | S24: Stock Summary Report — Row 27 | T24: =IF(A24="Missing SKU",0,1/COUNTIFS($A$2:$A$2503,A24)) | U24: N/A — Generic/Unbranded
A25: Missing SKU | B25: 2 LED OWL LIGHT | C25: Lighting & Electrical | D25: LED Accessories | K25: 2 LED OWL LIGHT (SKU: Missing SKU). | L25: 2 | M25: 0 | N25: 80 | O25: 2 | P25: 0 | Q25: 160 | R25: Source-Parsed | S25: Stock Summary Report — Row 28 | T25: =IF(A25="Missing SKU",0,1/COUNTIFS($A$2:$A$2503,A25)) | U25: N/A — Generic/Unbranded
A26: 349 | B26: 200 NS ROL GOLD KIT (349) | C26: Drive & Transmission | D26: Chains & Sprockets | G26: GOLD | K26: 200 NS ROL GOLD KIT (349) (SKU: 349). Colour: GOLD. | L26: 0 | M26: 2777 | N26: 2561 | O26: 0 | P26: 0 | Q26: 0 | R26: Source-Parsed | S26: Stock Summary Report — Row 29 | T26: =IF(A26="Missing SKU",0,1/COUNTIFS($A$2:$A$2503,A26)) | U26: Probable Match | V26: https://www.indiamart.com/proddetail/chain-sprocket-kit-for-ktm-duke-390-23302980233.html
A27: Missing SKU | B27: 3000 4T PLUS 15W50 2.5LTR | C27: Engine Oils & Lubricants | E27: Motul | K27: 3000 4T PLUS 15W50 2.5LTR (SKU: Missing SKU). Brand: Motul. | L27: 1 | M27: 0 | N27: 990 | O27: 1 | P27: 0 | Q27: 711.04 | R27: Source-Parsed | S27: Stock Summary Report — Row 30 | T27: =IF(A27="Missing SKU",0,1/COUNTIFS($A$2:$A$2503,A27)) | U27: Externally Verified | V27: https://www.indiamart.com/proddetail/motul-3000-4t-plus-bike-engine-oil-2852554385712.html
A28: Missing SKU | B28: 3100 GOLD 20W50 4T 1 LTR | C28: Engine Oils & Lubricants | E28: Motul | G28: GOLD | K28: 3100 GOLD 20W50 4T 1 LTR (SKU: Missing SKU). Brand: Motul. Colour: GOLD. | L28: 0 | M28: 0 | N28: 440 | O28: 0 | P28: 0 | Q28: 0 | R28: Source-Parsed | S28: Stock Summary Report — Row 31 | T28: =IF(A28="Missing SKU",0,1/COUNTIFS($A$2:$A$2503,A28)) | U28: Externally Verified | V28: https://www.moglix.com/motul-3100-gold-4t-20w50-1l-technosynthese-synthetic-blend-engine-oil/mp/msng9vnvmer6kp
A29: Missing SKU | B29: 3100 GOLD 20W50 4T 1LTR | C29: Engine Oils & Lubricants | E29: Motul | G29: GOLD | K29: 3100 GOLD 20W50 4T 1LTR (SKU: Missing SKU). Brand: Motul. Colour: GOLD. | L29: 2 | M29: 560 | N29: 445 | O29: 2 | P29: 0 | Q29: 754.28 | R29: Source-Parsed | S29: Stock Summary Report — Row 32 | T29: =IF(A29="Missing SKU",0,1/COUNTIFS($A$2:$A$2503,A29)) | U29: Externally Verified | V29: https://www.moglix.com/motul-3100-gold-4t-20w50-1l-technosynthese-synthetic-blend-engine-oil/mp/msng9vnvmer6kp
A30: Missing SKU | B30: 3100 GOLD 4T 15W 50 1.7LTR | C30: Engine Oils & Lubricants | E30: Motul | G30: GOLD | K30: 3100 GOLD 4T 15W 50 1.7LTR (SKU: Missing SKU). Brand: Motul. Colour: GOLD. | L30: 2 | M30: 949 | N30: 860 | O30: 2 | P30: 0 | Q30: 1253.29 | R30: Source-Parsed | S30: Stock Summary Report — Row 33 | T30: =IF(A30="Missing SKU",0,1/COUNTIFS($A$2:$A$2503,A30)) | U30: Externally Verified | V30: https://www.moglix.com/motul-3100-gold-4t-20w50-1l-technosynthese-synthetic-blend-engine-oil/mp/msng9vnvmer6kp
A31: Missing SKU | B31: 3100 GOLD 4T 15W 50 2.5LTR | C31: Engine Oils & Lubricants | E31: Motul | G31: GOLD | K31: 3100 GOLD 4T 15W 50 2.5LTR (SKU: Missing SKU). Brand: Motul. Colour: GOLD. | L31: 4 | M31: 0 | N31: 1220 | O31: 4 | P31: 0 | Q31: 3291.6 | R31: Source-Parsed | S31: Stock Summary Report — Row 34 | T31: =IF(A31="Missing SKU",0,1/COUNTIFS($A$2:$A$2503,A31)) | U31: Externally Verified | V31: https://www.moglix.com/motul-3100-gold-4t-20w50-1l-technosynthese-synthetic-blend-engine-oil/mp/msng9vnvmer6kp
A32: Missing SKU | B32: 3100 GOLD 4T 20W50 1.2 LTR | C32: Engine Oils & Lubricants | E32: Motul | G32: GOLD | K32: 3100 GOLD 4T 20W50 1.2 LTR (SKU: Missing SKU). Brand: Motul. Colour: GOLD. | L32: 4 | M32: 640 | N32: 530 | O32: 4 | P32: 0 | Q32: 1796.7 | R32: Source-Parsed | S32: Stock Summary Report — Row 35 | T32: =IF(A32="Missing SKU",0,1/COUNTIFS($A$2:$A$2503,A32)) | U32: Externally Verified | V32: https://www.moglix.com/motul-3100-gold-4t-20w50-1l-technosynthese-synthetic-blend-engine-oil/mp/msng9vnvmer6kp
A33: Missing SKU | B33: 3M TAPE | C33: Tools & Workshop Equipment | D33: Consumables | E33: 3M | F33: TAPE | K33: 3M TAPE (SKU: Missing SKU). Brand: 3M. Model/Series: TAPE. | L33: 8 | M33: 181 | N33: 98 | O33: 8 | P33: 0 | Q33: 649.15 | R33: Source-Parsed | S33: Stock Summary Report — Row 36 | T33: =IF(A33="Missing SKU",0,1/COUNTIFS($A$2:$A$2503,A33)) | U33: Not Found Externally | V33: https://www.meesho.com/vhb-double-sided-tape-heavy-duty-3m-super-strong-mounting-tape-holds-67kg-all-weather-waterproof-tape-for-indoor-outdoor-automotive-use/p/ay0723
A34: Missing SKU | B34: 4-SIDED GRIP MOBILE HOLDER MOUNT - BLACK | C34: Mirrors & Handlebar Accessories | D34: Handlebar Controls | G34: BLACK | K34: 4-SIDED GRIP MOBILE HOLDER MOUNT - BLACK (SKU: Missing SKU). Colour: BLACK. | L34: 1 | M34: 1800 | N34: 1651 | O34: 1 | P34: 0 | Q34: 744.59 | R34: Source-Parsed | S34: Stock Summary Report — Row 37 | T34: =IF(A34="Missing SKU",0,1/COUNTIFS($A$2:$A$2503,A34)) | U34: N/A — Generic/Unbranded
A35: Missing SKU | B35: 4100 ECOMILE 5W 30 3.5LTR | C35: Engine Oils & Lubricants | E35: Motul | K35: 4100 ECOMILE 5W 30 3.5LTR (SKU: Missing SKU). Brand: Motul. | L35: 0 | M35: 0 | N35: 1380 | O35: 0 | P35: 0 | Q35: 0 | R35: Source-Parsed | S35: Stock Summary Report — Row 38 | T35: =IF(A35="Missing SKU",0,1/COUNTIFS($A$2:$A$2503,A35)) | U35: Externally Verified | V35: https://www.indiamart.com/proddetail/3-5l-motul-4100-ecomile-engine-oil-25254926462.html?pos=1&nh=Y
A36: Missing SKU | B36: 5100 4T 10W40 1 LTR | C36: Engine Oils & Lubricants | E36: Motul | K36: 5100 4T 10W40 1 LTR (SKU: Missing SKU). Brand: Motul. | L36: 0 | M36: 530 | N36: 530 | O36: 0 | P36: 0 | Q36: 0 | R36: Source-Parsed | S36: Stock Summary Report — Row 39 | T36: =IF(A36="Missing SKU",0,1/COUNTIFS($A$2:$A$2503,A36)) | U36: Externally Verified | V36: https://www.flipkart.com/motul-5100-4t-10w-40-semi-synthetic-grade-blend-engine-oil/p/itm7ad23809aa27d?pid=VLUFQ2MGTGSNUYNM&lid=LSTVLUFQ2MGTGSNUYNMFOVLHB&hl_lid&marketplace=FLIPKART&fm=eyJ3dHAiOiJhdGxhc19hZHNfaG9yaXpvbnRhbF9wbXVfY2Fyb3VzZWwiLCJwcnB0Ijoic3AifQ%3D%3D&affid=inf_c5ff269b-5175-478e-94e6-163fafa5
A37: Missing SKU | B37: 5100 4T 15W50 1 LTR | C37: Engine Oils & Lubricants | E37: Motul | K37: 5100 4T 15W50 1 LTR (SKU: Missing SKU). Brand: Motul. | L37: 4 | M37: 0 | N37: 500 | O37: 4 | P37: 0 | Q37: 1695 | R37: Source-Parsed | S37: Stock Summary Report — Row 40 | T37: =IF(A37="Missing SKU",0,1/COUNTIFS($A$2:$A$2503,A37)) | U37: Externally Verified | V37: https://www.ubuy.co.in/product/M0VGPFMS-motul-5100-4t-15w50-1litter-104080
A38: Missing SKU | B38: 55 LTR TOP BOX METAL LGP | C38: Luggage & Storage | D38: Top Boxes | E38: LGP | K38: 55 LTR TOP BOX METAL LGP (SKU: Missing SKU). Brand: LGP. | L38: 3 | M38: 10200 | N38: 13500 | O38: 3 | P38: 0 | Q38: 16302.97 | R38: Source-Parsed | S38: Stock Summary Report — Row 41 | T38: =IF(A38="Missing SKU",0,1/COUNTIFS($A$2:$A$2503,A38)) | U38: Externally Verified | V38: https://lgpindia.com/collections/top-box?page=3
A39: Missing SKU | B39: 66 BHP BALACLAVA BLACK | C39: Riding Jackets & Apparel | D39: Headwear | E39: 66 BHP | F39: BALACLAVA | G39: BLACK | K39: 66 BHP BALACLAVA BLACK (SKU: Missing SKU). Brand: 66 BHP. Model/Series: BALACLAVA. Colour: BLACK. | L39: 103 | M39: 250 | N39: 124.5 | O39: 103 | P39: 0 | Q39: 11860 | R39: Source-Parsed | S39: Stock Summary Report — Row 42 | T39: =IF(A39="Missing SKU",0,1/COUNTIFS($A$2:$A$2503,A39)) | U39: Externally Verified | V39: https://www.66bhp.com/products/motorcycle-balaclava?_pos=1&_sid=19eced32e&_ss=r
A40: Missing SKU | B40: 66 BHP BAMBOO TERY SOCKS | C40: Riding Jackets & Apparel | D40: Socks | E40: 66 BHP | F40: BAMBOO TERY SOCKS | K40: 66 BHP BAMBOO TERY SOCKS (SKU: Missing SKU). Brand: 66 BHP. Model/Series: BAMBOO TERY SOCKS. | L40: 2 | M40: 499 | N40: 299.5 | O40: 2 | P40: 0 | Q40: 570.48 | R40: Source-Parsed | S40: Stock Summary Report — Row 43 | T40: =IF(A40="Missing SKU",0,1/COUNTIFS($A$2:$A$2503,A40)) | U40: Externally Verified | V40: https://66bhp.com/products/bamboo-socks-men-women-buy-2-get-1-free-combo-pack
...

Sheet Lists
A1: Categories | B1: Subcategories | C1: Status | D1: External Verification
A2: Body Parts & Panels | B2: Arm Sleeves | C2: Source-Parsed | D2: Externally Verified
A3: Boots & Footwear | B3: Auxiliary Lights | C3: Needs Verification | D3: Probable Match
A4: Braking Components | B4: Axles & Spacers | D4: Not Found Externally
A5: Cables & Controls | B5: Backrests | D5: N/A — Generic/Unbranded
A6: Covers | B6: Bags & Backpacks
A7: Crash Protection | B7: Base Layers
A8: Drive & Transmission | B8: Batteries & Chargers
A9: Electronics | B9: Bike Covers
A10: Engine Components | B10: Bluetooth Intercoms
A11: Engine Oils & Lubricants | B11: Boot Rain Covers
A12: Exhaust System | B12: Bottle Holders & Hydration
A13: Gloves | B13: Bulbs
A14: Helmets | B14: Bungee Cords
A15: Lighting & Electrical | B15: Camera & Mounts
A16: Locks & Security | B16: Carriers & Racks
A17: Luggage & Storage | B17: Chain Cleaners
... A30: Unclassified — Needs Verification | B30: Handguards
B31: Handlebar Controls
B32: Headlight Guards
B33: Headlights
B34: Headwear
B35: Heat Shields
B36: Helmet Accessories
B37: Helmet Locks
B38: Horns
B39: Ignition Components
B40: Indicators & Flashers
B41: Jerry Cans
B42: Jerseys
... B73: Winglets

Sheet Category Summary
A1: Category | B1: Subcategory | C1: Distinct Products | D1: Unique SKUs | E1: Total Stock Quantity | F1: Needs Verification
A2: Body Parts & Panels | C2: =COUNTIFS(ProductMaster!$C$2:$C$2503,A2,ProductMaster!$D$2:$D$2503,B2) | D2: =ROUND(SUMIFS(ProductMaster!$T$2:$T$2503,ProductMaster!$C$2:$C$2503,A2,ProductMaster!$D$2:$D$2503,B2),0) | E2: =SUMIFS(ProductMaster!$L$2:$L$2503,ProductMaster!$C$2:$C$2503,A2,ProductMaster!$D$2:$D$2503,B2) | F2: =COUNTIFS(ProductMaster!$C$2:$C$2503,A2,ProductMaster!$D$2:$D$2503,B2,ProductMaster!$R$2:$R$2503,"Needs Verification")
A3: Body Parts & Panels | B3: Backrests | C3: =COUNTIFS(ProductMaster!$C$2:$C$2503,A3,ProductMaster!$D$2:$D$2503,B3) | D3: =ROUND(SUMIFS(ProductMaster!$T$2:$T$2503,ProductMaster!$C$2:$C$2503,A3,ProductMaster!$D$2:$D$2503,B3),0) | E3: =SUMIFS(ProductMaster!$L$2:$L$2503,ProductMaster!$C$2:$C$2503,A3,ProductMaster!$D$2:$D$2503,B3) | F3: =COUNTIFS(ProductMaster!$C$2:$C$2503,A3,ProductMaster!$D$2:$D$2503,B3,ProductMaster!$R$2:$R$2503,"Needs Verification")
A4: Body Parts & Panels | B4: Footrests | C4: =COUNTIFS(ProductMaster!$C$2:$C$2503,A4,ProductMaster!$D$2:$D$2503,B4) | D4: =ROUND(SUMIFS(ProductMaster!$T$2:$T$2503,ProductMaster!$C$2:$C$2503,A4,ProductMaster!$D$2:$D$2503,B4),0) | E4: =SUMIFS(ProductMaster!$L$2:$L$2503,ProductMaster!$C$2:$C$2503,A4,ProductMaster!$D$2:$D$2503,B4) | F4: =COUNTIFS(ProductMaster!$C$2:$C$2503,A4,ProductMaster!$D$2:$D$2503,B4,ProductMaster!$R$2:$R$2503,"Needs Verification")
A5: Body Parts & Panels | B5: Grab Rails | C5: =COUNTIFS(ProductMaster!$C$2:$C$2503,A5,ProductMaster!$D$2:$D$2503,B5) | D5: =ROUND(SUMIFS(ProductMaster!$T$2:$T$2503,ProductMaster!$C$2:$C$2503,A5,ProductMaster!$D$2:$D$2503,B5),0) | E5: =SUMIFS(ProductMaster!$L$2:$L$2503,ProductMaster!$C$2:$C$2503,A5,ProductMaster!$D$2:$D$2503,B5) | F5: =COUNTIFS(ProductMaster!$C$2:$C$2503,A5,ProductMaster!$D$2:$D$2503,B5,ProductMaster!$R$2:$R$2503,"Needs Verification")
A6: Body Parts & Panels | B6: Handguards | C6: =COUNTIFS(ProductMaster!$C$2:$C$2503,A6,ProductMaster!$D$2:$D$2503,B6) | D6: =ROUND(SUMIFS(ProductMaster!$T$2:$T$2503,ProductMaster!$C$2:$C$2503,A6,ProductMaster!$D$2:$D$2503,B6),0) | E6: =SUMIFS(ProductMaster!$L$2:$L$2503,ProductMaster!$C$2:$C$2503,A6,ProductMaster!$D$2:$D$2503,B6) | F6: =COUNTIFS(ProductMaster!$C$2:$C$2503,A6,ProductMaster!$D$2:$D$2503,B6,ProductMaster!$R$2:$R$2503,"Needs Verification")
A7: Body Parts & Panels | B7: Number Plates | C7: =COUNTIFS(ProductMaster!$C$2:$C$2503,A7,ProductMaster!$D$2:$D$2503,B7) | D7: =ROUND(SUMIFS(ProductMaster!$T$2:$T$2503,ProductMaster!$C$2:$C$2503,A7,ProductMaster!$D$2:$D$2503,B7),0) | E7: =SUMIFS(ProductMaster!$L$2:$L$2503,ProductMaster!$C$2:$C$2503,A7,ProductMaster!$D$2:$D$2503,B7) | F7: =COUNTIFS(ProductMaster!$C$2:$C$2503,A7,ProductMaster!$D$2:$D$2503,B7,ProductMaster!$R$2:$R$2503,"Needs Verification")
A8: Body Parts & Panels | B8: Seats | C8: =COUNTIFS(ProductMaster!$C$2:$C$2503,A8,ProductMaster!$D$2:$D$2503,B8) | D8: =ROUND(SUMIFS(ProductMaster!$T$2:$T$2503,ProductMaster!$C$2:$C$2503,A8,ProductMaster!$D$2:$D$2503,B8),0) | E8: =SUMIFS(ProductMaster!$L$2:$L$2503,ProductMaster!$C$2:$C$2503,A8,ProductMaster!$D$2:$D$2503,B8) | F8: =COUNTIFS(ProductMaster!$C$2:$C$2503,A8,ProductMaster!$D$2:$D$2503,B8,ProductMaster!$R$2:$R$2503,"Needs Verification")
A9: Body Parts & Panels | B9: Side Stand Accessories | C9: =COUNTIFS(ProductMaster!$C$2:$C$2503,A9,ProductMaster!$D$2:$D$2503,B9) | D9: =ROUND(SUMIFS(ProductMaster!$T$2:$T$2503,ProductMaster!$C$2:$C$2503,A9,ProductMaster!$D$2:$D$2503,B9),0) | E9: =SUMIFS(ProductMaster!$L$2:$L$2503,ProductMaster!$C$2:$C$2503,A9,ProductMaster!$D$2:$D$2503,B9) | F9: =COUNTIFS(ProductMaster!$C$2:$C$2503,A9,ProductMaster!$D$2:$D$2503,B9,ProductMaster!$R$2:$R$2503,"Needs Verification")
A10: Body Parts & Panels | B10: Tail Tidies | C10: =COUNTIFS(ProductMaster!$C$2:$C$2503,A10,ProductMaster!$D$2:$D$2503,B10) | D10: =ROUND(SUMIFS(ProductMaster!$T$2:$T$2503,ProductMaster!$C$2:$C$2503,A10,ProductMaster!$D$2:$D$2503,B10),0) | E10: =SUMIFS(ProductMaster!$L$2:$L$2503,ProductMaster!$C$2:$C$2503,A10,ProductMaster!$D$2:$D$2503,B10) | F10: =COUNTIFS(ProductMaster!$C$2:$C$2503,A10,ProductMaster!$D$2:$D$2503,B10,ProductMaster!$R$2:$R$2503,"Needs Verification")
A11: Body Parts & Panels | B11: Tank Pads | C11: =COUNTIFS(ProductMaster!$C$2:$C$2503,A11,ProductMaster!$D$2:$D$2503,B11) | D11: =ROUND(SUMIFS(ProductMaster!$T$2:$T$2503,ProductMaster!$C$2:$C$2503,A11,ProductMaster!$D$2:$D$2503,B11),0) | E11: =SUMIFS(ProductMaster!$L$2:$L$2503,ProductMaster!$C$2:$C$2503,A11,ProductMaster!$D$2:$D$2503,B11) | F11: =COUNTIFS(ProductMaster!$C$2:$C$2503,A11,ProductMaster!$D$2:$D$2503,B11,ProductMaster!$R$2:$R$2503,"Needs Verification")
A12: Body Parts & Panels | B12: Windscreens | C12: =COUNTIFS(ProductMaster!$C$2:$C$2503,A12,ProductMaster!$D$2:$D$2503,B12) | D12: =ROUND(SUMIFS(ProductMaster!$T$2:$T$2503,ProductMaster!$C$2:$C$2503,A12,ProductMaster!$D$2:$D$2503,B12),0) | E12: =SUMIFS(ProductMaster!$L$2:$L$2503,ProductMaster!$C$2:$C$2503,A12,ProductMaster!$D$2:$D$2503,B12) | F12: =COUNTIFS(ProductMaster!$C$2:$C$2503,A12,ProductMaster!$D$2:$D$2503,B12,ProductMaster!$R$2:$R$2503,"Needs Verification")
A13: Body Parts & Panels | B13: Winglets | C13: =COUNTIFS(ProductMaster!$C$2:$C$2503,A13,ProductMaster!$D$2:$D$2503,B13) | D13: =ROUND(SUMIFS(ProductMaster!$T$2:$T$2503,ProductMaster!$C$2:$C$2503,A13,ProductMaster!$D$2:$D$2503,B13),0) | E13: =SUMIFS(ProductMaster!$L$2:$L$2503,ProductMaster!$C$2:$C$2503,A13,ProductMaster!$D$2:$D$2503,B13) | F13: =COUNTIFS(ProductMaster!$C$2:$C$2503,A13,ProductMaster!$D$2:$D$2503,B13,ProductMaster!$R$2:$R$2503,"Needs Verification")
A14: Boots & Footwear | C14: =COUNTIFS(ProductMaster!$C$2:$C$2503,A14,ProductMaster!$D$2:$D$2503,B14) | D14: =ROUND(SUMIFS(ProductMaster!$T$2:$T$2503,ProductMaster!$C$2:$C$2503,A14,ProductMaster!$D$2:$D$2503,B14),0) | E14: =SUMIFS(ProductMaster!$L$2:$L$2503,ProductMaster!$C$2:$C$2503,A14,ProductMaster!$D$2:$D$2503,B14) | F14: =COUNTIFS(ProductMaster!$C$2:$C$2503,A14,ProductMaster!$D$2:$D$2503,B14,ProductMaster!$R$2:$R$2503,"Needs Verification")
A15: Braking Components | C15: =COUNTIFS(ProductMaster!$C$2:$C$2503,A15,ProductMaster!$D$2:$D$2503,B15) | D15: =ROUND(SUMIFS(ProductMaster!$T$2:$T$2503,ProductMaster!$C$2:$C$2503,A15,ProductMaster!$D$2:$D$2503,B15),0) | E15: =SUMIFS(ProductMaster!$L$2:$L$2503,ProductMaster!$C$2:$C$2503,A15,ProductMaster!$D$2:$D$2503,B15) | F15: =COUNTIFS(ProductMaster!$C$2:$C$2503,A15,ProductMaster!$D$2:$D$2503,B15,ProductMaster!$R$2:$R$2503,"Needs Verification")
A16: Cables & Controls | C16: =COUNTIFS(ProductMaster!$C$2:$C$2503,A16,ProductMaster!$D$2:$D$2503,B16) | D16: =ROUND(SUMIFS(ProductMaster!$T$2:$T$2503,ProductMaster!$C$2:$C$2503,A16,ProductMaster!$D$2:$D$2503,B16),0) | E16: =SUMIFS(ProductMaster!$L$2:$L$2503,ProductMaster!$C$2:$C$2503,A16,ProductMaster!$D$2:$D$2503,B16) | F16: =COUNTIFS(ProductMaster!$C$2:$C$2503,A16,ProductMaster!$D$2:$D$2503,B16,ProductMaster!$R$2:$R$2503,"Needs Verification")
A17: Covers | B17: Bike Covers | C17: =COUNTIFS(ProductMaster!$C$2:$C$2503,A17,ProductMaster!$D$2:$D$2503,B17) | D17: =ROUND(SUMIFS(ProductMaster!$T$2:$T$2503,ProductMaster!$C$2:$C$2503,A17,ProductMaster!$D$2:$D$2503,B17),0) | E17: =SUMIFS(ProductMaster!$L$2:$L$2503,ProductMaster!$C$2:$C$2503,A17,ProductMaster!$D$2:$D$2503,B17) | F17: =COUNTIFS(ProductMaster!$C$2:$C$2503,A17,ProductMaster!$D$2:$D$2503,B17,ProductMaster!$R$2:$R$2503,"Needs Verification")
A18: Covers | B18: Boot Rain Covers | C18: =COUNTIFS(ProductMaster!$C$2:$C$2503,A18,ProductMaster!$D$2:$D$2503,B18) | D18: =ROUND(SUMIFS(ProductMaster!$T$2:$T$2503,ProductMaster!$C$2:$C$2503,A18,ProductMaster!$D$2:$D$2503,B18),0) | E18: =SUMIFS(ProductMaster!$L$2:$L$2503,ProductMaster!$C$2:$C$2503,A18,ProductMaster!$D$2:$D$2503,B18) | F18: =COUNTIFS(ProductMaster!$C$2:$C$2503,A18,ProductMaster!$D$2:$D$2503,B18,ProductMaster!$R$2:$R$2503,"Needs Verification")
A19: Crash Protection | B19: Crash Guards & Sliders | C19: =COUNTIFS(ProductMaster!$C$2:$C$2503,A19,ProductMaster!$D$2:$D$2503,B19) | D19: =ROUND(SUMIFS(ProductMaster!$T$2:$T$2503,ProductMaster!$C$2:$C$2503,A19,ProductMaster!$D$2:$D$2503,B19),0) | E19: =SUMIFS(ProductMaster!$L$2:$L$2503,ProductMaster!$C$2:$C$2503,A19,ProductMaster!$D$2:$D$2503,B19) | F19: =COUNTIFS(ProductMaster!$C$2:$C$2503,A19,ProductMaster!$D$2:$D$2503,B19,ProductMaster!$R$2:$R$2503,"Needs Verification")
A20: Crash Protection | B20: Radiator Guards | C20: =COUNTIFS(ProductMaster!$C$2:$C$2503,A20,ProductMaster!$D$2:$D$2503,B20) | D20: =ROUND(SUMIFS(ProductMaster!$T$2:$T$2503,ProductMaster!$C$2:$C$2503,A20,ProductMaster!$D$2:$D$2503,B20),0) | E20: =SUMIFS(ProductMaster!$L$2:$L$2503,ProductMaster!$C$2:$C$2503,A20,ProductMaster!$D$2:$D$2503,B20) | F20: =COUNTIFS(ProductMaster!$C$2:$C$2503,A20,ProductMaster!$D$2:$D$2503,B20,ProductMaster!$R$2:$R$2503,"Needs Verification")
A21: Drive & Transmission | B21: Chains & Sprockets | C21: =COUNTIFS(ProductMaster!$C$2:$C$2503,A21,ProductMaster!$D$2:$D$2503,B21) | D21: =ROUND(SUMIFS(ProductMaster!$T$2:$T$2503,ProductMaster!$C$2:$C$2503,A21,ProductMaster!$D$2:$D$2503,B21),0) | E21: =SUMIFS(ProductMaster!$L$2:$L$2503,ProductMaster!$C$2:$C$2503,A21,ProductMaster!$D$2:$D$2503,B21) | F21: =COUNTIFS(ProductMaster!$C$2:$C$2503,A21,ProductMaster!$D$2:$D$2503,B21,ProductMaster!$R$2:$R$2503,"Needs Verification")
A22: Drive & Transmission | B22: Clutch Components | C22: =COUNTIFS(ProductMaster!$C$2:$C$2503,A22,ProductMaster!$D$2:$D$2503,B22) | D22: =ROUND(SUMIFS(ProductMaster!$T$2:$T$2503,ProductMaster!$C$2:$C$2503,A22,ProductMaster!$D$2:$D$2503,B22),0) | E22: =SUMIFS(ProductMaster!$L$2:$L$2503,ProductMaster!$C$2:$C$2503,A22,ProductMaster!$D$2:$D$2503,B22) | F22: =COUNTIFS(ProductMaster!$C$2:$C$2503,A22,ProductMaster!$D$2:$D$2503,B22,ProductMaster!$R$2:$R$2503,"Needs Verification")
A23: Electronics | B23: Bluetooth Intercoms | C23: =COUNTIFS(ProductMaster!$C$2:$C$2503,A23,ProductMaster!$D$2:$D$2503,B23) | D23: =ROUND(SUMIFS(ProductMaster!$T$2:$T$2503,ProductMaster!$C$2:$C$2503,A23,ProductMaster!$D$2:$D$2503,B23),0) | E23: =SUMIFS(ProductMaster!$L$2:$L$2503,ProductMaster!$C$2:$C$2503,A23,ProductMaster!$D$2:$D$2503,B23) | F23: =COUNTIFS(ProductMaster!$C$2:$C$2503,A23,ProductMaster!$D$2:$D$2503,B23,ProductMaster!$R$2:$R$2503,"Needs Verification")
A24: Electronics | B24: Camera & Mounts | C24: =COUNTIFS(ProductMaster!$C$2:$C$2503,A24,ProductMaster!$D$2:$D$2503,B24) | D24: =ROUND(SUMIFS(ProductMaster!$T$2:$T$2503,ProductMaster!$C$2:$C$2503,A24,ProductMaster!$D$2:$D$2503,B24),0) | E24: =SUMIFS(ProductMaster!$L$2:$L$2503,ProductMaster!$C$2:$C$2503,A24,ProductMaster!$D$2:$D$2503,B24) | F24: =COUNTIFS(ProductMaster!$C$2:$C$2503,A24,ProductMaster!$D$2:$D$2503,B24,ProductMaster!$R$2:$R$2503,"Needs Verification")
A25: Electronics | B25: GPS Trackers | C25: =COUNTIFS(ProductMaster!$C$2:$C$2503,A25,ProductMaster!$D$2:$D$2503,B25) | D25: =ROUND(SUMIFS(ProductMaster!$T$2:$T$2503,ProductMaster!$C$2:$C$2503,A25,ProductMaster!$D$2:$D$2503,B25),0) | E25: =SUMIFS(ProductMaster!$L$2:$L$2503,ProductMaster!$C$2:$C$2503,A25,ProductMaster!$D$2:$D$2503,B25) | F25: =COUNTIFS(ProductMaster!$C$2:$C$2503,A25,ProductMaster!$D$2:$D$2503,B25,ProductMaster!$R$2:$R$2503,"Needs Verification")
A26: Electronics | B26: Mobile Accessories | C26: =COUNTIFS(ProductMaster!$C$2:$C$2503,A26,ProductMaster!$D$2:$D$2503,B26) | D26: =ROUND(SUMIFS(ProductMaster!$T$2:$T$2503,ProductMaster!$C$2:$C$2503,A26,ProductMaster!$D$2:$D$2503,B26),0) | E26: =SUMIFS(ProductMaster!$L$2:$L$2503,ProductMaster!$C$2:$C$2503,A26,ProductMaster!$D$2:$D$2503,B26) | F26: =COUNTIFS(ProductMaster!$C$2:$C$2503,A26,ProductMaster!$D$2:$D$2503,B26,ProductMaster!$R$2:$R$2503,"Needs Verification")
A27: Electronics | B27: Mobile Holders & Mounts | C27: =COUNTIFS(ProductMaster!$C$2:$C$2503,A27,ProductMaster!$D$2:$D$2503,B27) | D27: =ROUND(SUMIFS(ProductMaster!$T$2:$T$2503,ProductMaster!$C$2:$C$2503,A27,ProductMaster!$D$2:$D$2503,B27),0) | E27: =SUMIFS(ProductMaster!$L$2:$L$2503,ProductMaster!$C$2:$C$2503,A27,ProductMaster!$D$2:$D$2503,B27) | F27: =COUNTIFS(ProductMaster!$C$2:$C$2503,A27,ProductMaster!$D$2:$D$2503,B27,ProductMaster!$R$2:$R$2503,"Needs Verification")
A28: Engine Components | B28: Filters | C28: =COUNTIFS(ProductMaster!$C$2:$C$2503,A28,ProductMaster!$D$2:$D$2503,B28) | D28: =ROUND(SUMIFS(ProductMaster!$T$2:$T$2503,ProductMaster!$C$2:$C$2503,A28,ProductMaster!$D$2:$D$2503,B28),0) | E28: =SUMIFS(ProductMaster!$L$2:$L$2503,ProductMaster!$C$2:$C$2503,A28,ProductMaster!$D$2:$D$2503,B28) | F28: =COUNTIFS(ProductMaster!$C$2:$C$2503,A28,ProductMaster!$D$2:$D$2503,B28,ProductMaster!$R$2:$R$2503,"Needs Verification")
... A30: Engine Components | B30: Spark Plugs | C30: =COUNTIFS(ProductMaster!$C$2:$C$2503,A30,ProductMaster!$D$2:$D$2503,B30) | D30: =ROUND(SUMIFS(ProductMaster!$T$2:$T$2503,ProductMaster!$C$2:$C$2503,A30,ProductMaster!$D$2:$D$2503,B30),0) | E30: =SUMIFS(ProductMaster!$L$2:$L$2503,ProductMaster!$C$2:$C$2503,A30,ProductMaster!$D$2:$D$2503,B30) | F30: =COUNTIFS(ProductMaster!$C$2:$C$2503,A30,ProductMaster!$D$2:$D$2503,B30,ProductMaster!$R$2:$R$2503,"Needs Verification")
A31: Engine Oils & Lubricants | C31: =COUNTIFS(ProductMaster!$C$2:$C$2503,A31,ProductMaster!$D$2:$D$2503,B31) | D31: =ROUND(SUMIFS(ProductMaster!$T$2:$T$2503,ProductMaster!$C$2:$C$2503,A31,ProductMaster!$D$2:$D$2503,B31),0) | E31: =SUMIFS(ProductMaster!$L$2:$L$2503,ProductMaster!$C$2:$C$2503,A31,ProductMaster!$D$2:$D$2503,B31) | F31: =COUNTIFS(ProductMaster!$C$2:$C$2503,A31,ProductMaster!$D$2:$D$2503,B31,ProductMaster!$R$2:$R$2503,"Needs Verification")
A32: Exhaust System | C32: =COUNTIFS(ProductMaster!$C$2:$C$2503,A32,ProductMaster!$D$2:$D$2503,B32) | D32: =ROUND(SUMIFS(ProductMaster!$T$2:$T$2503,ProductMaster!$C$2:$C$2503,A32,ProductMaster!$D$2:$D$2503,B32),0) | E32: =SUMIFS(ProductMaster!$L$2:$L$2503,ProductMaster!$C$2:$C$2503,A32,ProductMaster!$D$2:$D$2503,B32) | F32: =COUNTIFS(ProductMaster!$C$2:$C$2503,A32,ProductMaster!$D$2:$D$2503,B32,ProductMaster!$R$2:$R$2503,"Needs Verification")
A33: Exhaust System | B33: Heat Shields | C33: =COUNTIFS(ProductMaster!$C$2:$C$2503,A33,ProductMaster!$D$2:$D$2503,B33) | D33: =ROUND(SUMIFS(ProductMaster!$T$2:$T$2503,ProductMaster!$C$2:$C$2503,A33,ProductMaster!$D$2:$D$2503,B33),0) | E33: =SUMIFS(ProductMaster!$L$2:$L$2503,ProductMaster!$C$2:$C$2503,A33,ProductMaster!$D$2:$D$2503,B33) | F33: =COUNTIFS(ProductMaster!$C$2:$C$2503,A33,ProductMaster!$D$2:$D$2503,B33,ProductMaster!$R$2:$R$2503,"Needs Verification")
A34: Gloves | C34: =COUNTIFS(ProductMaster!$C$2:$C$2503,A34,ProductMaster!$D$2:$D$2503,B34) | D34: =ROUND(SUMIFS(ProductMaster!$T$2:$T$2503,ProductMaster!$C$2:$C$2503,A34,ProductMaster!$D$2:$D$2503,B34),0) | E34: =SUMIFS(ProductMaster!$L$2:$L$2503,ProductMaster!$C$2:$C$2503,A34,ProductMaster!$D$2:$D$2503,B34) | F34: =COUNTIFS(ProductMaster!$C$2:$C$2503,A34,ProductMaster!$D$2:$D$2503,B34,ProductMaster!$R$2:$R$2503,"Needs Verification")
A35: Helmets | C35: =COUNTIFS(ProductMaster!$C$2:$C$2503,A35,ProductMaster!$D$2:$D$2503,B35) | D35: =ROUND(SUMIFS(ProductMaster!$T$2:$T$2503,ProductMaster!$C$2:$C$2503,A35,ProductMaster!$D$2:$D$2503,B35),0) | E35: =SUMIFS(ProductMaster!$L$2:$L$2503,ProductMaster!$C$2:$C$2503,A35,ProductMaster!$D$2:$D$2503,B35) | F35: =COUNTIFS(ProductMaster!$C$2:$C$2503,A35,ProductMaster!$D$2:$D$2503,B35,ProductMaster!$R$2:$R$2503,"Needs Verification")
A36: Helmets | B36: Helmet Accessories | C36: =COUNTIFS(ProductMaster!$C$2:$C$2503,A36,ProductMaster!$D$2:$D$2503,B36) | D36: =ROUND(SUMIFS(ProductMaster!$T$2:$T$2503,ProductMaster!$C$2:$C$2503,A36,ProductMaster!$D$2:$D$2503,B36),0) | E36: =SUMIFS(ProductMaster!$L$2:$L$2503,ProductMaster!$C$2:$C$2503,A36,ProductMaster!$D$2:$D$2503,B36) | F36: =COUNTIFS(ProductMaster!$C$2:$C$2503,A36,ProductMaster!$D$2:$D$2503,B36,ProductMaster!$R$2:$R$2503,"Needs Verification")
A37: Helmets | B37: Riding Eyewear | C37: =COUNTIFS(ProductMaster!$C$2:$C$2503,A37,ProductMaster!$D$2:$D$2503,B37) | D37: =ROUND(SUMIFS(ProductMaster!$T$2:$T$2503,ProductMaster!$C$2:$C$2503,A37,ProductMaster!$D$2:$D$2503,B37),0) | E37: =SUMIFS(ProductMaster!$L$2:$L$2503,ProductMaster!$C$2:$C$2503,A37,ProductMaster!$D$2:$D$2503,B37) | F37: =COUNTIFS(ProductMaster!$C$2:$C$2503,A37,ProductMaster!$D$2:$D$2503,B37,ProductMaster!$R$2:$R$2503,"Needs Verification")
A38: Lighting & Electrical | C38: =COUNTIFS(ProductMaster!$C$2:$C$2503,A38,ProductMaster!$D$2:$D$2503,B38) | D38: =ROUND(SUMIFS(ProductMaster!$T$2:$T$2503,ProductMaster!$C$2:$C$2503,A38,ProductMaster!$D$2:$D$2503,B38),0) | E38: =SUMIFS(ProductMaster!$L$2:$L$2503,ProductMaster!$C$2:$C$2503,A38,ProductMaster!$D$2:$D$2503,B38) | F38: =COUNTIFS(ProductMaster!$C$2:$C$2503,A38,ProductMaster!$D$2:$D$2503,B38,ProductMaster!$R$2:$R$2503,"Needs Verification")
A39: Lighting & Electrical | B39: Auxiliary Lights | C39: =COUNTIFS(ProductMaster!$C$2:$C$2503,A39,ProductMaster!$D$2:$D$2503,B39) | D39: =ROUND(SUMIFS(ProductMaster!$T$2:$T$2503,ProductMaster!$C$2:$C$2503,A39,ProductMaster!$D$2:$D$2503,B39),0) | E39: =SUMIFS(ProductMaster!$L$2:$L$2503,ProductMaster!$C$2:$C$2503,A39,ProductMaster!$D$2:$D$2503,B39) | F39: =COUNTIFS(ProductMaster!$C$2:$C$2503,A39,ProductMaster!$D$2:$D$2503,B39,ProductMaster!$R$2:$R$2503,"Needs Verification")
A40: Lighting & Electrical | B40: Batteries & Chargers | C40: =COUNTIFS(ProductMaster!$C$2:$C$2503,A40,ProductMaster!$D$2:$D$2503,B40) | D40: =ROUND(SUMIFS(ProductMaster!$T$2:$T$2503,ProductMaster!$C$2:$C$2503,A40,ProductMaster!$D$2:$D$2503,B40),0) | E40: =SUMIFS(ProductMaster!$L$2:$L$2503,ProductMaster!$C$2:$C$2503,A40,ProductMaster!$D$2:$D$2503,B40) | F40: =COUNTIFS(ProductMaster!$C$2:$C$2503,A40,ProductMaster!$D$2:$D$2503,B40,ProductMaster!$R$2:$R$2503,"Needs Verification")
A41: Lighting & Electrical | B41: Bulbs | C41: =COUNTIFS(ProductMaster!$C$2:$C$2503,A41,ProductMaster!$D$2:$D$2503,B41) | D41: =ROUND(SUMIFS(ProductMaster!$T$2:$T$2503,ProductMaster!$C$2:$C$2503,A41,ProductMaster!$D$2:$D$2503,B41),0) | E41: =SUMIFS(ProductMaster!$L$2:$L$2503,ProductMaster!$C$2:$C$2503,A41,ProductMaster!$D$2:$D$2503,B41) | F41: =COUNTIFS(ProductMaster!$C$2:$C$2503,A41,ProductMaster!$D$2:$D$2503,B41,ProductMaster!$R$2:$R$2503,"Needs Verification")
...

Sheet SKU & Data Quality Audit
A1: Issue Type | B1: SKU | C1: Product Name | D1: Source Reference | E1: Details | F1: Recommended Action
A2: Missing SKU | B2: Missing SKU | C2: BOOT RAIN COVER | D2: Stock Summary Report — Row 5 | E2: No SKU/item code found in source item name. | F2: Assign an internal SKU or confirm with supplier records.
A3: Missing SKU | B3: Missing SKU | C3: CARRIER | D3: Stock Summary Report — Row 6 | E3: No SKU/item code found in source item name. | F3: Assign an internal SKU or confirm with supplier records.
A4: Missing SKU | B4: Missing SKU | C4: CARRIER&BACKREST | D4: Stock Summary Report — Row 7 | E4: No SKU/item code found in source item name. | F4: Assign an internal SKU or confirm with supplier records.
A5: Missing SKU | B5: Missing SKU | C5: CG WITH SLIDER | D5: Stock Summary Report — Row 8 | E5: No SKU/item code found in source item name. | F5: Assign an internal SKU or confirm with supplier records.
A6: Missing SKU | B6: Missing SKU | C6: CHAIN CLEANER BRUSH RED AND BLACK | D6: Stock Summary Report — Row 9 | E6: No SKU/item code found in source item name. | F6: Assign an internal SKU or confirm with supplier records.
A7: Missing SKU | B7: Missing SKU | C7: CLOTH | D7: Stock Summary Report — Row 10 | E7: No SKU/item code found in source item name. | F7: Assign an internal SKU or confirm with supplier records.
A8: Missing SKU | B8: Missing SKU | C8: CRASHGUARD | D8: Stock Summary Report — Row 11 | E8: No SKU/item code found in source item name. | F8: Assign an internal SKU or confirm with supplier records.
A9: Missing SKU | B9: Missing SKU | C9: HANDLE | D9: Stock Summary Report — Row 12 | E9: No SKU/item code found in source item name. | F9: Assign an internal SKU or confirm with supplier records.
A10: Missing SKU | B10: Missing SKU | C10: HAZARD | D10: Stock Summary Report — Row 13 | E10: No SKU/item code found in source item name. | F10: Assign an internal SKU or confirm with supplier records.
A11: Missing SKU | B11: Missing SKU | C11: HEAD MOUNT | D11: Stock Summary Report — Row 14 | E11: No SKU/item code found in source item name. | F11: Assign an internal SKU or confirm with supplier records.
A12: Missing SKU | B12: Missing SKU | C12: HEADLIGHT SHIELD | D12: Stock Summary Report — Row 15 | E12: No SKU/item code found in source item name. | F12: Assign an internal SKU or confirm with supplier records.
... A2551: Category assigned by fallback rule | B2551: Missing SKU | C2551: YEZDI ADVENTURE / ROADSTER (401 NF) | D2551: Stock Summary Report — Row 2511 | E2551: Classification based on 'model-plus-code guess'; not confirmed from explicit product keywords. | F2551: Manually confirm the category is correct.

Sheet Source Reconciliation
A1: Source Sheet | B1: Source Row | C1: Original Item Name | D1: Code Found in Name | E1: Original Stock Qty | F1: Original Stock Value | G1: Final SKU | H1: Final Product Name | I1: Final Category | J1: Outcome
A2: Stock Summary Report | B2: 5 | C2: **BOOT RAIN COVER | D2: — | E2: 4 | F2: 169.48 | G2: Missing SKU | H2: BOOT RAIN COVER | I2: Covers | J2: Mapped to Product Master
A3: Stock Summary Report | B3: 6 | C3: **CARRIER | D3: — | E3: -1 | F3: 0 | G3: Missing SKU | H3: CARRIER | I3: Luggage & Storage | J3: Mapped to Product Master
A4: Stock Summary Report | B4: 7 | C4: **CARRIER&BACKREST | D4: — | E4: 0 | F4: 0 | G4: Missing SKU | H4: CARRIER&BACKREST | I4: Body Parts & Panels | J4: Mapped to Product Master
A5: Stock Summary Report | B5: 8 | C5: **CG WITH SLIDER | D5: — | E5: 1 | F5: 351.56 | G5: Missing SKU | H5: CG WITH SLIDER | I5: Crash Protection | J5: Mapped to Product Master
A6: Stock Summary Report | B6: 9 | C6: **CHAIN CLEANER BRUSH RED AND BLACK | D6: — | E6: -2 | F6: 0 | G6: Missing SKU | H6: CHAIN CLEANER BRUSH RED AND BLACK | I6: Maintenance & Cleaning | J6: Mapped to Product Master
A7: Stock Summary Report | B7: 10 | C7: **CLOTH | D7: — | E7: 0 | F7: 0 | G7: Missing SKU | H7: CLOTH | I7: Maintenance & Cleaning | J7: Mapped to Product Master
A8: Stock Summary Report | B8: 11 | C8: **CRASHGUARD | D8: — | E8: 1 | F8: 359.38 | G8: Missing SKU | H8: CRASHGUARD | I8: Crash Protection | J8: Mapped to Product Master
A9: Stock Summary Report | B9: 12 | C9: **HANDLE | D9: — | E9: -1 | F9: 0 | G9: Missing SKU | H9: HANDLE | I9: Mirrors & Handlebar Accessories | J9: Mapped to Product Master
A10: Stock Summary Report | B10: 13 | C10: **HAZARD | D10: — | E10: 7 | F10: 593.18 | G10: Missing SKU | H10: HAZARD | I10: Lighting & Electrical | J10: Mapped to Product Master
A11: Stock Summary Report | B11: 14 | C11: **HEAD MOUNT | D11: — | E11: 1 | F11: 218.75 | G11: Missing SKU | H11: HEAD MOUNT | I11: Unclassified — Needs Verification | J11: Mapped to Product Master
A12: Stock Summary Report | B12: 15 | C12: **HEADLIGHT SHIELD | D12: — | E12: 0 | F12: 0 | G12: Missing SKU | H12: HEADLIGHT SHIELD | I12: Lighting & Electrical | J12: Mapped to Product Master
A13: Stock Summary Report | B13: 16 | C13: **MICRO FIBER AND HELMET CAP | D13: — | E13: 13 | F13: 123.76 | G13: Missing SKU | H13: MICRO FIBER AND HELMET CAP | I13: Helmets | J13: Mapped to Product Master
... A2508: Stock Summary Report | B2508: 2511 | C2508: YEZDI ADVENTURE / ROADSTER (401 NF) | D2508: — | E2508: 1 | F2508: 1754 | G2508: Missing SKU | H2508: YEZDI ADVENTURE / ROADSTER (401 NF) | I2508: Drive & Transmission | J2508: Mapped to Product Master

Sheet Vehicle Compatibility
A1: SKU | B1: Product SKU | C1: Product Name | D1: Compatible Bike Make | E1: Compatible Bike Model | F1: Source Reference | G1: Notes
A2: Missing SKU | B2: Missing SKU | C2: 77200ABW110S XPULSE RALLY SEAT | D2: HERO | E2: XPULSE | F2: Stock Summary Report — Row 76 | G2: Fitment extracted from source item name; verify against manufacturer fitment charts before promising fit.
A3: Missing SKU | B3: Missing SKU | C3: 77200ACY130S XPULSE210 RALLY SEAT | D3: HERO | E3: XPULSE210 | F3: Stock Summary Report — Row 77 | G3: Fitment extracted from source item name; verify against manufacturer fitment charts before promising fit.
A4: BEN0074 | B4: BEN0074 | C4: R15 V3 MT15 BEND BS4 | D4: YAMAHA | E4: R15 V3 | F4: Stock Summary Report — Row 209 | G4: Fitment extracted from source item name; verify against manufacturer fitment charts before promising fit.
A5: BEN0075 | B5: BEN0075 | C5: R15 V3 MT15 BEND BS6 | D5: YAMAHA | E5: R15 V3 | F5: Stock Summary Report — Row 210 | G5: Fitment extracted from source item name; verify against manufacturer fitment charts before promising fit.
A6: BEN11492 | B6: BEN11492 | C6: KTM ADV 390 BEND PIPE | D6: KTM | E6: KTM | F6: Stock Summary Report — Row 212 | G6: Fitment extracted from source item name; verify against manufacturer fitment charts before promising fit.
A7: BEN14268 | B7: BEN14268 | C7: R15 V4 DUAL SENSOR BEND PIPE SILVER | D7: YAMAHA | E7: R15 V4 | F7: Stock Summary Report — Row 213 | G7: Fitment extracted from source item name; verify against manufacturer fitment charts before promising fit.
A8: Missing SKU | B8: Missing SKU | C8: BIZEN HERO XPULSE 210 GPS/SMARTPHONE MOUNT | D8: HERO | E8: XPULSE 210 | F8: Stock Summary Report — Row 218 | G8: Fitment extracted from source item name; verify against manufacturer fitment charts before promising fit.
A9: Missing SKU | B9: Missing SKU | C9: BIZEN HERO XPULSE 210 PREMIUM HEADLIGHT GUARD WITH TRANSPARENT AND YELLOW TINT GLASSES | D9: HERO | E9: XPULSE 210 | F9: Stock Summary Report — Row 219 | G9: Fitment extracted from source item name; verify against manufacturer fitment charts before promising fit.
A10: Missing SKU | B10: Missing SKU | C10: Bizen Yezdi Adventure Gen 2 (2024 -2025) XXL Top Plate / Rear Rack Plate with seat rest | D10: JAWA/YEZDI | E10: YEZDI | F10: Stock Summary Report — Row 221 | G10: Fitment extracted from source item name; verify against manufacturer fitment charts before promising fit.
A11: Missing SKU | B11: Missing SKU | C11: Bizen Yezdi Adventure Gen 2 (2024 -2025) Aluminium Bash Plate | D11: JAWA/YEZDI | E11: YEZDI | F11: Stock Summary Report — Row 222 | G11: Fitment extracted from source item name; verify against manufacturer fitment charts before promising fit.
A12: Missing SKU | B12: Missing SKU | C12: Bizen Yezdi Adventure Gen 2 (2024 -2025) Front Brake Oil Reservoir Guard/Cover - Black | D12: JAWA/YEZDI | E12: YEZDI | F12: Stock Summary Report — Row 223 | G12: Fitment extracted from source item name; verify against manufacturer fitment charts before promising fit.
... A360: Missing SKU | B360: Missing SKU | C360: YEZDI ADVENTURE / ROADSTER (401 NF) | D360: JAWA/YEZDI | E360: YEZDI | F360: Stock Summary Report — Row 2511 | G360: Fitment extracted from source item name; verify against manufacturer fitment charts before promising fit.
